Workbook

Sheet Master Tracker
A1: ID | B1: Topic | C1: Problem | D1: Difficulty | E1: Contest ROI | F1: Interview ROI | G1: Pattern | H1: Company | I1: NeetCode | J1: Blind75 | K1: Target(min) | L1: Status | M1: Attempts | N1: Actual(min) | O1: First Solve | P1: R+3 | Q1: R+7 | R1: R+21 | S1: R+45 | T1: Explain(1-5) | U1: Mistake Tag | V1: Notes
A2: 1 | B2: Arrays | C2: Two Sum | D2: Easy | E2: ★★★★★ | F2: ★★★★★ | G2: Arrays | H2: All | I2: Yes | J2: Yes | K2: 15 | L2: Not Started | M2: 0 | P2: =IF(O2="","",O2+3) | Q2: =IF(O2="","",O2+7) | R2: =IF(O2="","",O2+21) | S2: =IF(O2="","",O2+45) | T2: 0
A3: 2 | B3: Arrays | C3: Group Anagrams | D3: Easy | E3: ★★★★★ | F3: ★★★★★ | G3: Arrays | H3: General | I3: Yes | K3: 15 | L3: Not Started | M3: 0 | P3: =IF(O3="","",O3+3) | Q3: =IF(O3="","",O3+7) | R3: =IF(O3="","",O3+21) | S3: =IF(O3="","",O3+45) | T3: 0
A4: 3 | B4: Arrays | C4: Top K Frequent | D4: Easy | E4: ★★★★★ | F4: ★★★★★ | G4: Arrays | H4: General | I4: Yes | K4: 15 | L4: Not Started | M4: 0 | P4: =IF(O4="","",O4+3) | Q4: =IF(O4="","",O4+7) | R4: =IF(O4="","",O4+21) | S4: =IF(O4="","",O4+45) | T4: 0
A5: 4 | B5: Arrays | C5: Product of Array Except Self | D5: Easy | E5: ★★★★★ | F5: ★★★★★ | G5: Arrays | H5: General | I5: Yes | K5: 15 | L5: Not Started | M5: 0 | P5: =IF(O5="","",O5+3) | Q5: =IF(O5="","",O5+7) | R5: =IF(O5="","",O5+21) | S5: =IF(O5="","",O5+45) | T5: 0
A6: 5 | B6: Arrays | C6: Longest Consecutive Sequence | D6: Easy | E6: ★★★★★ | F6: ★★★★★ | G6: Arrays | H6: General | I6: Yes | K6: 15 | L6: Not Started | M6: 0 | P6: =IF(O6="","",O6+3) | Q6: =IF(O6="","",O6+7) | R6: =IF(O6="","",O6+21) | S6: =IF(O6="","",O6+45) | T6: 0
A7: 6 | B7: Arrays | C7: Subarray Sum Equals K | D7: Easy | E7: ★★★★★ | F7: ★★★★★ | G7: Arrays | H7: General | I7: Yes | K7: 15 | L7: Not Started | M7: 0 | P7: =IF(O7="","",O7+3) | Q7: =IF(O7="","",O7+7) | R7: =IF(O7="","",O7+21) | S7: =IF(O7="","",O7+45) | T7: 0
A8: 7 | B8: Arrays | C8: Arrays Practice 7 | D8: Easy | E8: ★★★☆☆ | F8: ★★★☆☆ | G8: Arrays | H8: General | K8: 15 | L8: Not Started | M8: 0 | P8: =IF(O8="","",O8+3) | Q8: =IF(O8="","",O8+7) | R8: =IF(O8="","",O8+21) | S8: =IF(O8="","",O8+45) | T8: 0
A9: 8 | B9: Arrays | C9: Arrays Practice 8 | D9: Easy | E9: ★★★☆☆ | F9: ★★★☆☆ | G9: Arrays | H9: General | K9: 15 | L9: Not Started | M9: 0 | P9: =IF(O9="","",O9+3) | Q9: =IF(O9="","",O9+7) | R9: =IF(O9="","",O9+21) | S9: =IF(O9="","",O9+45) | T9: 0
A10: 9 | B10: Arrays | C10: Arrays Practice 9 | D10: Medium | E10: ★★★☆☆ | F10: ★★★☆☆ | G10: Arrays | H10: General | K10: 30 | L10: Not Started | M10: 0 | P10: =IF(O10="","",O10+3) | Q10: =IF(O10="","",O10+7) | R10: =IF(O10="","",O10+21) | S10: =IF(O10="","",O10+45) | T10: 0
A11: 10 | B11: Arrays | C11: Arrays Practice 10 | D11: Medium | E11: ★★★☆☆ | F11: ★★★☆☆ | G11: Arrays | H11: General | K11: 30 | L11: Not Started | M11: 0 | P11: =IF(O11="","",O11+3) | Q11: =IF(O11="","",O11+7) | R11: =IF(O11="","",O11+21) | S11: =IF(O11="","",O11+45) | T11: 0
A12: 11 | B12: Arrays | C12: Arrays Practice 11 | D12: Medium | E12: ★★★☆☆ | F12: ★★★☆☆ | G12: Arrays | H12: General | K12: 30 | L12: Not Started | M12: 0 | P12: =IF(O12="","",O12+3) | Q12: =IF(O12="","",O12+7) | R12: =IF(O12="","",O12+21) | S12: =IF(O12="","",O12+45) | T12: 0
A13: 12 | B13: Arrays | C13: Arrays Practice 12 | D13: Medium | E13: ★★★☆☆ | F13: ★★★☆☆ | G13: Arrays | H13: General | K13: 30 | L13: Not Started | M13: 0 | P13: =IF(O13="","",O13+3) | Q13: =IF(O13="","",O13+7) | R13: =IF(O13="","",O13+21) | S13: =IF(O13="","",O13+45) | T13: 0
A14: 13 | B14: Arrays | C14: Arrays Practice 13 | D14: Medium | E14: ★★★☆☆ | F14: ★★★☆☆ | G14: Arrays | H14: General | K14: 30 | L14: Not Started | M14: 0 | P14: =IF(O14="","",O14+3) | Q14: =IF(O14="","",O14+7) | R14: =IF(O14="","",O14+21) | S14: =IF(O14="","",O14+45) | T14: 0
A15: 14 | B15: Arrays | C15: Arrays Practice 14 | D15: Medium | E15: ★★★☆☆ | F15: ★★★☆☆ | G15: Arrays | H15: General | K15: 30 | L15: Not Started | M15: 0 | P15: =IF(O15="","",O15+3) | Q15: =IF(O15="","",O15+7) | R15: =IF(O15="","",O15+21) | S15: =IF(O15="","",O15+45) | T15: 0
A16: 15 | B16: Arrays | C16: Arrays Practice 15 | D16: Medium | E16: ★★★☆☆ | F16: ★★★☆☆ | G16: Arrays | H16: General | K16: 30 | L16: Not Started | M16: 0 | P16: =IF(O16="","",O16+3) | Q16: =IF(O16="","",O16+7) | R16: =IF(O16="","",O16+21) | S16: =IF(O16="","",O16+45) | T16: 0
A17: 16 | B17: Arrays | C17: Arrays Practice 16 | D17: Medium | E17: ★★★☆☆ | F17: ★★★☆☆ | G17: Arrays | H17: General | K17: 30 | L17: Not Started | M17: 0 | P17: =IF(O17="","",O17+3) | Q17: =IF(O17="","",O17+7) | R17: =IF(O17="","",O17+21) | S17: =IF(O17="","",O17+45) | T17: 0
A18: 17 | B18: Arrays | C18: Arrays Practice 17 | D18: Medium | E18: ★★★☆☆ | F18: ★★★☆☆ | G18: Arrays | H18: General | K18: 30 | L18: Not Started | M18: 0 | P18: =IF(O18="","",O18+3) | Q18: =IF(O18="","",O18+7) | R18: =IF(O18="","",O18+21) | S18: =IF(O18="","",O18+45) | T18: 0
A19: 18 | B19: Arrays | C19: Arrays Practice 18 | D19: Medium | E19: ★★★☆☆ | F19: ★★★☆☆ | G19: Arrays | H19: General | K19: 30 | L19: Not Started | M19: 0 | P19: =IF(O19="","",O19+3) | Q19: =IF(O19="","",O19+7) | R19: =IF(O19="","",O19+21) | S19: =IF(O19="","",O19+45) | T19: 0
... A26: 25 | B26: Arrays | C26: Arrays Practice 25 | D26: Hard | E26: ★★★☆☆ | F26: ★★★☆☆ | G26: Arrays | H26: General | K26: 40 | L26: Not Started | M26: 0 | P26: =IF(O26="","",O26+3) | Q26: =IF(O26="","",O26+7) | R26: =IF(O26="","",O26+21) | S26: =IF(O26="","",O26+45) | T26: 0
A27: 26 | B27: Two Pointers | C27: 3Sum | D27: Easy | E27: ★★★★★ | F27: ★★★★★ | G27: Two Pointers | H27: Meta/Google | I27: Yes | J27: Yes | K27: 15 | L27: Not Started | M27: 0 | P27: =IF(O27="","",O27+3) | Q27: =IF(O27="","",O27+7) | R27: =IF(O27="","",O27+21) | S27: =IF(O27="","",O27+45) | T27: 0
A28: 27 | B28: Two Pointers | C28: Container With Most Water | D28: Easy | E28: ★★★★★ | F28: ★★★★★ | G28: Two Pointers | H28: General | I28: Yes | K28: 15 | L28: Not Started | M28: 0 | P28: =IF(O28="","",O28+3) | Q28: =IF(O28="","",O28+7) | R28: =IF(O28="","",O28+21) | S28: =IF(O28="","",O28+45) | T28: 0
A29: 28 | B29: Two Pointers | C29: Longest Substring Without Repeating Characters | D29: Easy | E29: ★★★★★ | F29: ★★★★★ | G29: Two Pointers | H29: General | I29: Yes | J29: Yes | K29: 15 | L29: Not Started | M29: 0 | P29: =IF(O29="","",O29+3) | Q29: =IF(O29="","",O29+7) | R29: =IF(O29="","",O29+21) | S29: =IF(O29="","",O29+45) | T29: 0
A30: 29 | B30: Two Pointers | C30: Character Replacement | D30: Easy | E30: ★★★★★ | F30: ★★★★★ | G30: Two Pointers | H30: General | I30: Yes | K30: 15 | L30: Not Started | M30: 0 | P30: =IF(O30="","",O30+3) | Q30: =IF(O30="","",O30+7) | R30: =IF(O30="","",O30+21) | S30: =IF(O30="","",O30+45) | T30: 0
A31: 30 | B31: Two Pointers | C31: Minimum Window Substring | D31: Easy | E31: ★★★★★ | F31: ★★★★★ | G31: Two Pointers | H31: General | I31: Yes | K31: 15 | L31: Not Started | M31: 0 | P31: =IF(O31="","",O31+3) | Q31: =IF(O31="","",O31+7) | R31: =IF(O31="","",O31+21) | S31: =IF(O31="","",O31+45) | T31: 0
A32: 31 | B32: Two Pointers | C32: Sliding Window Maximum | D32: Easy | E32: ★★★★★ | F32: ★★★★★ | G32: Two Pointers | H32: General | I32: Yes | K32: 15 | L32: Not Started | M32: 0 | P32: =IF(O32="","",O32+3) | Q32: =IF(O32="","",O32+7) | R32: =IF(O32="","",O32+21) | S32: =IF(O32="","",O32+45) | T32: 0
A33: 32 | B33: Two Pointers | C33: Trapping Rain Water | D33: Easy | E33: ★★★★★ | F33: ★★★★★ | G33: Two Pointers | H33: General | I33: Yes | K33: 15 | L33: Not Started | M33: 0 | P33: =IF(O33="","",O33+3) | Q33: =IF(O33="","",O33+7) | R33: =IF(O33="","",O33+21) | S33: =IF(O33="","",O33+45) | T33: 0
A34: 33 | B34: Two Pointers | C34: Two Pointers Practice 8 | D34: Easy | E34: ★★★☆☆ | F34: ★★★☆☆ | G34: Two Pointers | H34: General | K34: 15 | L34: Not Started | M34: 0 | P34: =IF(O34="","",O34+3) | Q34: =IF(O34="","",O34+7) | R34: =IF(O34="","",O34+21) | S34: =IF(O34="","",O34+45) | T34: 0
A35: 34 | B35: Two Pointers | C35: Two Pointers Practice 9 | D35: Medium | E35: ★★★☆☆ | F35: ★★★☆☆ | G35: Two Pointers | H35: General | K35: 30 | L35: Not Started | M35: 0 | P35: =IF(O35="","",O35+3) | Q35: =IF(O35="","",O35+7) | R35: =IF(O35="","",O35+21) | S35: =IF(O35="","",O35+45) | T35: 0
A36: 35 | B36: Two Pointers | C36: Two Pointers Practice 10 | D36: Medium | E36: ★★★☆☆ | F36: ★★★☆☆ | G36: Two Pointers | H36: General | K36: 30 | L36: Not Started | M36: 0 | P36: =IF(O36="","",O36+3) | Q36: =IF(O36="","",O36+7) | R36: =IF(O36="","",O36+21) | S36: =IF(O36="","",O36+45) | T36: 0
A37: 36 | B37: Two Pointers | C37: Two Pointers Practice 11 | D37: Medium | E37: ★★★☆☆ | F37: ★★★☆☆ | G37: Two Pointers | H37: General | K37: 30 | L37: Not Started | M37: 0 | P37: =IF(O37="","",O37+3) | Q37: =IF(O37="","",O37+7) | R37: =IF(O37="","",O37+21) | S37: =IF(O37="","",O37+45) | T37: 0
A38: 37 | B38: Two Pointers | C38: Two Pointers Practice 12 | D38: Medium | E38: ★★★☆☆ | F38: ★★★☆☆ | G38: Two Pointers | H38: General | K38: 30 | L38: Not Started | M38: 0 | P38: =IF(O38="","",O38+3) | Q38: =IF(O38="","",O38+7) | R38: =IF(O38="","",O38+21) | S38: =IF(O38="","",O38+45) | T38: 0
A39: 38 | B39: Two Pointers | C39: Two Pointers Practice 13 | D39: Medium | E39: ★★★☆☆ | F39: ★★★☆☆ | G39: Two Pointers | H39: General | K39: 30 | L39: Not Started | M39: 0 | P39: =IF(O39="","",O39+3) | Q39: =IF(O39="","",O39+7) | R39: =IF(O39="","",O39+21) | S39: =IF(O39="","",O39+45) | T39: 0
A40: 39 | B40: Two Pointers | C40: Two Pointers Practice 14 | D40: Medium | E40: ★★★☆☆ | F40: ★★★☆☆ | G40: Two Pointers | H40: General | K40: 30 | L40: Not Started | M40: 0 | P40: =IF(O40="","",O40+3) | Q40: =IF(O40="","",O40+7) | R40: =IF(O40="","",O40+21) | S40: =IF(O40="","",O40+45) | T40: 0
A41: 40 | B41: Two Pointers | C41: Two Pointers Practice 15 | D41: Medium | E41: ★★★☆☆ | F41: ★★★☆☆ | G41: Two Pointers | H41: General | K41: 30 | L41: Not Started | M41: 0 | P41: =IF(O41="","",O41+3) | Q41: =IF(O41="","",O41+7) | R41: =IF(O41="","",O41+21) | S41: =IF(O41="","",O41+45) | T41: 0
A42: 41 | B42: Two Pointers | C42: Two Pointers Practice 16 | D42: Medium | E42: ★★★☆☆ | F42: ★★★☆☆ | G42: Two Pointers | H42: General | K42: 30 | L42: Not Started | M42: 0 | P42: =IF(O42="","",O42+3) | Q42: =IF(O42="","",O42+7) | R42: =IF(O42="","",O42+21) | S42: =IF(O42="","",O42+45) | T42: 0
A43: 42 | B43: Two Pointers | C43: Two Pointers Practice 17 | D43: Medium | E43: ★★★☆☆ | F43: ★★★☆☆ | G43: Two Pointers | H43: General | K43: 30 | L43: Not Started | M43: 0 | P43: =IF(O43="","",O43+3) | Q43: =IF(O43="","",O43+7) | R43: =IF(O43="","",O43+21) | S43: =IF(O43="","",O43+45) | T43: 0
A44: 43 | B44: Two Pointers | C44: Two Pointers Practice 18 | D44: Medium | E44: ★★★☆☆ | F44: ★★★☆☆ | G44: Two Pointers | H44: General | K44: 30 | L44: Not Started | M44: 0 | P44: =IF(O44="","",O44+3) | Q44: =IF(O44="","",O44+7) | R44: =IF(O44="","",O44+21) | S44: =IF(O44="","",O44+45) | T44: 0
A45: 44 | B45: Two Pointers | C45: Two Pointers Practice 19 | D45: Medium | E45: ★★★☆☆ | F45: ★★★☆☆ | G45: Two Pointers | H45: General | K45: 30 | L45: Not Started | M45: 0 | P45: =IF(O45="","",O45+3) | Q45: =IF(O45="","",O45+7) | R45: =IF(O45="","",O45+21) | S45: =IF(O45="","",O45+45) | T45: 0
... A51: 50 | B51: Two Pointers | C51: Two Pointers Practice 25 | D51: Hard | E51: ★★★☆☆ | F51: ★★★☆☆ | G51: Two Pointers | H51: General | K51: 40 | L51: Not Started | M51: 0 | P51: =IF(O51="","",O51+3) | Q51: =IF(O51="","",O51+7) | R51: =IF(O51="","",O51+21) | S51: =IF(O51="","",O51+45) | T51: 0
...

Sheet Dashboard
A1: SDE-2 DSA OS (Final)
A2: Current Rating | B2: 1512 | D2: Topic | E2: Solved
A3: Goal | B3: 1800 | D3: Arrays | E3: =COUNTIFS('Master Tracker'!B:B,D3,'Master Tracker'!L:L,"Solved")+COUNTIFS('Master Tracker'!B:B,D3,'Master Tracker'!L:L,"Re-solved")
A4: Total Problems | B4: 250 | D4: Two Pointers | E4: =COUNTIFS('Master Tracker'!B:B,D4,'Master Tracker'!L:L,"Solved")+COUNTIFS('Master Tracker'!B:B,D4,'Master Tracker'!L:L,"Re-solved")
A5: Solved | B5: =COUNTIF('Master Tracker'!L:L,"Solved")+COUNTIF('Master Tracker'!L:L,"Re-solved") | D5: Binary Search | E5: =COUNTIFS('Master Tracker'!B:B,D5,'Master Tracker'!L:L,"Solved")+COUNTIFS('Master Tracker'!B:B,D5,'Master Tracker'!L:L,"Re-solved")
A6: Completion % | B6: =B5/B4 | D6: Prefix Sum | E6: =COUNTIFS('Master Tracker'!B:B,D6,'Master Tracker'!L:L,"Solved")+COUNTIFS('Master Tracker'!B:B,D6,'Master Tracker'!L:L,"Re-solved")
A7: High ROI Solved | B7: =COUNTIFS('Master Tracker'!E:E,"★★★★★",'Master Tracker'!L:L,"Solved")+COUNTIFS('Master Tracker'!E:E,"★★★★★",'Master Tracker'!L:L,"Re-solved") | D7: Greedy | E7: =COUNTIFS('Master Tracker'!B:B,D7,'Master Tracker'!L:L,"Solved")+COUNTIFS('Master Tracker'!B:B,D7,'Master Tracker'!L:L,"Re-solved")
A8: Avg Solve Time | B8: =AVERAGEIF('Master Tracker'!N:N,">0") | D8: Trees | E8: =COUNTIFS('Master Tracker'!B:B,D8,'Master Tracker'!L:L,"Solved")+COUNTIFS('Master Tracker'!B:B,D8,'Master Tracker'!L:L,"Re-solved")
D9: Heaps | E9: =COUNTIFS('Master Tracker'!B:B,D9,'Master Tracker'!L:L,"Solved")+COUNTIFS('Master Tracker'!B:B,D9,'Master Tracker'!L:L,"Re-solved")
D10: Graphs | E10: =COUNTIFS('Master Tracker'!B:B,D10,'Master Tracker'!L:L,"Solved")+COUNTIFS('Master Tracker'!B:B,D10,'Master Tracker'!L:L,"Re-solved")
D11: Dynamic Programming | E11: =COUNTIFS('Master Tracker'!B:B,D11,'Master Tracker'!L:L,"Solved")+COUNTIFS('Master Tracker'!B:B,D11,'Master Tracker'!L:L,"Re-solved")
D12: Bit Manipulation | E12: =COUNTIFS('Master Tracker'!B:B,D12,'Master Tracker'!L:L,"Solved")+COUNTIFS('Master Tracker'!B:B,D12,'Master Tracker'!L:L,"Re-solved")

Sheet Daily Planner
A1: Today's 90-Minute Plan
A3: Warm-up | B3: 1 Easy (15 min)
A4: Core | B4: 1 Medium (30 min)
A5: Stretch | B5: 1 Medium/Hard (30 min)
A6: Review | B6: 15 min spaced repetition

Sheet Contest Log
A1: Date | B1: Contest | C1: Rating Before | D1: Rating After | E1: Q1 | F1: Q2 | G1: Q3 | H1: Q4 | I1: Penalty | J1: Takeaway
C2: 1512
C3: =D2
C4: =D3
C5: =D4
C6: =D5
C7: =D6
C8: =D7
C9: =D8
C10: =D9
C11: =D10
C12: =D11
C13: =D12
C14: =D13
... C29: =D28

Sheet Company Focus
A1: Company | B1: Priority Topics | C1: Must-do Problems
A2: Amazon | B2: Arrays, Trees, Graphs | C2: Two Sum; Number of Islands; Diameter; Coin Change
A3: Google | B3: Binary Search, Graphs, DP | C3: Koko; LCA; LIS; Cheapest Flights
A4: Meta | B4: Arrays, Trees | C4: 3Sum; House Robber; LCA
A5: Microsoft | B5: Trees, Graphs | C5: Number of Islands; Course Schedule
A6: Uber | B6: Graphs, Heaps | C6: Network Delay; K Closest Points
A7: Atlassian | B7: Hash Maps, Graphs | C7: Course Schedule; Top K Frequent

Sheet Pattern Bible
A1: Pattern | B1: Recognition Cue | C1: Template | D1: Common Mistake
A2: Sliding Window | B2: Longest/Shortest subarray | C2: expand/shrink | D2: forget shrink
A3: Binary Search on Answer | B3: minimize/maximize | C3: while(low<high) | D3: mid update
A4: Prefix Sum | B4: subarray sum | C4: hash map | D4: missing sum=0
A5: DFS | B5: tree height/path | C5: postorder | D5: global state
A6: BFS | B6: shortest path | C6: queue | D6: late visited
A7: Heap | B7: top-k/stream | C7: priority_queue | D7: wrong heap
A8: Union Find | B8: connectivity | C8: parent/rank | D8: no compression
A9: DP | B9: optimal substructure | C9: state transition | D9: bad state

Sheet 12-Week Heatmap
A1: 84-Day Consistency Grid
B2: Mon | C2: Tue | D2: Wed | E2: Thu | F2: Fri | G2: Sat | H2: Sun
B3: 26 | C3: 27 | D3: 28 | E3: 29 | F3: 30 | G3: 31 | H3: 1
B4: 2 | C4: 3 | D4: 4 | E4: 5 | F4: 6 | G4: 7 | H4: 8
B5: 9 | C5: 10 | D5: 11 | E5: 12 | F5: 13 | G5: 14 | H5: 15
B6: 16 | C6: 17 | D6: 18 | E6: 19 | F6: 20 | G6: 21 | H6: 22
B7: 23 | C7: 24 | D7: 25 | E7: 26 | F7: 27 | G7: 28 | H7: 29
B8: 30 | C8: 1 | D8: 2 | E8: 3 | F8: 4 | G8: 5 | H8: 6
B9: 7 | C9: 8 | D9: 9 | E9: 10 | F9: 11 | G9: 12 | H9: 13
B10: 14 | C10: 15 | D10: 16 | E10: 17 | F10: 18 | G10: 19 | H10: 20
B11: 21 | C11: 22 | D11: 23 | E11: 24 | F11: 25 | G11: 26 | H11: 27
B12: 28 | C12: 29 | D12: 30 | E12: 31 | F12: 1 | G12: 2 | H12: 3
B13: 4 | C13: 5 | D13: 6 | E13: 7 | F13: 8 | G13: 9 | H13: 10
B14: 11 | C14: 12 | D14: 13 | E14: 14 | F14: 15 | G14: 16 | H14: 17

Sheet Interview Readiness
A1: Area | B1: Target | C1: Current (update monthly)
A2: Arrays | B2: 95
A3: Binary Search | B3: 90
A4: Graphs | B4: 85
A5: Trees | B5: 90
A6: DP | B6: 80
A7: Communication | B7: 90
A8: System Design | B8: 70
A9: LLD | B9: 70

Sheet 180-Day Roadmap
A1: Month | B1: Focus | C1: Goal
A2: 1 | B2: Arrays + Two Pointers | C2: Speed
A3: 2 | B3: Binary Search + Prefix Sum | C3: Pattern recognition
A4: 3 | B4: Trees + Heaps | C4: Implementation
A5: 4 | B5: Graphs + DP | C5: Interview mediums
A6: 5 | B6: Mixed + Company prep | C6: Mock interviews
A7: 6 | B7: Revision + Contests | C7: 1800-ready
